Workbook

Sheet Proyecciones
B1: Año 1 | C1: Año 2 | D1: Año 3
A2: Costos fijos mensuales | B2: =Estimaciones!C5 -> 11845685 | C2: =Estimaciones!D5 -> 16343896 | D2: =Estimaciones!E5 -> 22598558
A3: Costo variable por institución/mes | B3: =Estimaciones!C28 -> 205085.4 | C3: =Estimaciones!D28 -> 215339.67 | D3: =Estimaciones!E28 -> 226106.65
A4: Margen de utilidad | B4: 30% | C4: 30% | D4: 30%
A7: Proyecciones mensuales | B7: Año 1 | N7: Año 2 | Z7: Año 3
B8: M1 | C8: M2 | D8: M3 | E8: M4 | F8: M5 | G8: M6 | H8: M7 | I8: M8 | J8: M9 | K8: M10 | L8: M11 | M8: M12 | N8: M1 | O8: M2 | P8: M3 | Q8: M4 | R8: M5 | S8: M6 | T8: M7 | U8: M8 | V8: M9 | W8: M10 | X8: M11 | Y8: M12 | Z8: M1 | AA8: M2 | AB8: M3 | AC8: M4 | AD8: M5 | AE8: M6 | AF8: M7 | AG8: M8 | AH8: M9 | AI8: M10 | AJ8: M11 | AK8: M12
A9: No. de instituciones | B9: 2 | C9: 4 | D9: 6 | E9: 8 | F9: 10 | G9: 12 | H9: 14 | I9: 16 | J9: 18 | K9: 20 | L9: 22 | M9: 24 | N9: =M9+5 -> 29 | O9: =N9+5 -> 34 | P9: =O9+5 -> 39 | Q9: =P9+5 -> 44 | R9: =Q9+5 -> 49 | S9: =R9+5 -> 54 | T9: =S9+5 -> 59 | U9: =T9+5 -> 64 | ... Y9: =X9+5 -> 84 | Z9: =Y9+9 -> 93 | AA9: =Z9+9 -> 102 | AB9: =AA9+9 -> 111 | AC9: =AB9+9 -> 120 | AD9: =AC9+9 -> 129 | AE9: =AD9+9 -> 138 | AF9: =AE9+9 -> 147 | AG9: =AF9+9 -> 156 | ... AK9: =AJ9+9 -> 192
A10: Costos totales | B10: =$B$2+($B$3*2) -> 12255856 | C10: =$B$2+($B$3*C9) -> 12666027 | D10: =$B$2+($B$3*D9) -> 13076198 | E10: =$B$2+($B$3*E9) -> 13486368 | F10: =$B$2+($B$3*F9) -> 13896539 | G10: =$B$2+($B$3*G9) -> 14306710 | H10: =$B$2+($B$3*H9) -> 14716881 | I10: =$B$2+($B$3*I9) -> 15127052 | J10: =$B$2+($B$3*J9) -> 15537222 | ... M10: =$B$2+($B$3*M9) -> 16767735 | N10: =$C$2+($C$3*N9) -> 22588746 | O10: =$C$2+($C$3*O9) -> 23665444 | P10: =$C$2+($C$3*P9) -> 24742143 | Q10: =$C$2+($C$3*Q9) -> 25818841 | R10: =$C$2+($C$3*R9) -> 26895539 | S10: =$C$2+($C$3*S9) -> 27972238 | T10: =$C$2+($C$3*T9) -> 29048936 | U10: =$C$2+($C$3*U9) -> 30125635 | ... Y10: =$C$2+($C$3*Y9) -> 34432428 | Z10: =$D$2+($D$3*Z9) -> 43626477 | AA10: =$D$2+($D$3*AA9) -> 45661437 | AB10: =$D$2+($D$3*AB9) -> 47696396 | AC10: =$D$2+($D$3*AC9) -> 49731356 | AD10: =$D$2+($D$3*AD9) -> 51766316 | AE10: =$D$2+($D$3*AE9) -> 53801276 | AF10: =$D$2+($D$3*AF9) -> 55836236 | AG10: =$D$2+($D$3*AG9) -> 57871196 | ... AK10: =$D$2+($D$3*AK9) -> 66011035
A11: Precio de venta | B11: 773217.68 | C11: =B11 -> 773217.68 | D11: =C11 -> 773217.68 | E11: =D11 -> 773217.68 | F11: =E11 -> 773217.68 | G11: =F11 -> 773217.68 | H11: =G11 -> 773217.68 | I11: =H11 -> 773217.68 | J11: =I11 -> 773217.68 | ... M11: =L11 -> 773217.68 | N11: 811878.56 | O11: 811878.56 | P11: 811878.56 | Q11: 811878.56 | R11: 811878.56 | S11: 811878.56 | T11: 811878.56 | U11: 811878.56 | V11: 811878.56 | W11: 811878.56 | X11: 811878.56 | Y11: 811878.56 | Z11: 852472.49 | AA11: 852472.49 | AB11: 852472.49 | AC11: 852472.49 | AD11: 852472.49 | AE11: 852472.49 | AF11: 852472.49 | AG11: 852472.49 | AH11: 852472.49 | AI11: 852472.49 | AJ11: 852472.49 | AK11: 852472.49
A12: Ingresos totales | B12: =B11*B9 -> 1546435.4 | C12: =C11*C9 -> 3092870.7 | D12: =D11*D9 -> 4639306.1 | E12: =E11*E9 -> 6185741.4 | F12: =F11*F9 -> 7732176.8 | G12: =G11*G9 -> 9278612.2 | H12: =H11*H9 -> 10825048 | I12: =I11*I9 -> 12371483 | ... AK12: =AK11*AK9 -> 1.6367472e+08
A13: Utilidad operativa (EBITDA) | B13: =B12-B10 -> -10709421 | C13: =C12-C10 -> -9573156 | D13: =D12-D10 -> -8436891.4 | E13: =E12-E10 -> -7300626.9 | F13: =F12-F10 -> -6164362.3 | G13: =G12-G10 -> -5028097.8 | H13: =H12-H10 -> -3891833.2 | I13: =I12-I10 -> -2755568.6 | ... AK13: =AK12-AK10 -> 97663683
K14: Punto de equilibrio: | L14: =B2/(L11-B3) -> 20.850224 | M14: =SUM(B13:M13) -> -53519586 | N14: Utilidad operativa (EBITDA) | X14: Utilidad operativa (EBITDA) | Y14: =SUM(N13:Y13) -> 2.0832662e+08 | AJ14: Utilidad operativa (EBITDA) | AK14: =SUM(Z13:AK13) -> 7.9990289e+08
A15: (-) Depreciaciones y amortizaciones (5% ingresos) | H15: =SUM(B10:J10) -> 1.2506885e+08 | K15: Ingresos totales: | L15: =L14*L11 -> 16121762 | M15: =M14*0.05 -> -2675979.3 | N15: (-) Depreciaciones y amortizaciones 2 al 5% | X15: (-) Depreciaciones y amortizaciones 2 al 5% | Y15: =Y14*0.05 -> 10416331 | AJ15: (-) Depreciaciones y amortizaciones 2 al 5% | AK15: =AK14*0.05 -> 39995144
A16: (-) Intereses / gastos financieros (3% costos) | K16: Costos totales: | L16: =L14*B3+B2 -> 16121762 | M16: =M14*0.03 -> -1605587.6 | N16: (-) Intereses (Gastos financieros) 0 al 3% | X16: (-) Intereses (Gastos financieros) 0 al 3% | Y16: =Y14*0.03 -> 6249798.6 | AJ16: (-) Intereses (Gastos financieros) 0 al 3% | AK16: =AK14*0.03 -> 23997087
A17: Utilidad antes de impuestos (EBT) | M17: =M14-M15-M16 -> -49238019 | N17: Utilidad antes de impuestos (EBT) | X17: Utilidad antes de impuestos (EBT) | Y17: =Y14-Y15-Y16 -> 1.9166049e+08 | AJ17: Utilidad antes de impuestos (EBT) | AK17: =AK14-AK15-AK16 -> 7.3591066e+08
A18: (-) Impuestos (Renta 35%) | M18: =M17*0.35 -> -17233307 | N18: (-) Impuestos (Renta 35%) | X18: (-) Impuestos (Renta 35%) | Y18: =Y17*0.35 -> 67081171 | AJ18: (-) Impuestos (Renta 35%) | AK18: =AK17*0.35 -> 2.5756873e+08
A19: Utilidad neta | M19: =M17-M18 -> -32004712 | N19: Utilidad Neta | X19: Utilidad Neta | Y19: =Y17-Y18 -> 1.2457932e+08 | AJ19: Utilidad Neta | AK19: =AK17-AK18 -> 4.7834193e+08 | AL19: =AK19/AK14 -> 0.598

Sheet Estimaciones
B2: Detalle de Costos
C3: Año 1 | D3: Año 2 | E3: Año 3 | F3: Descripción
B5: Subtotal Costos fijos mensuales | C5: =SUM(C7:C12) -> 11845685 | D5: =SUM(D7:D12) -> 16343896 | E5: =SUM(E7:E12) -> 22598558
B7: Desarrollador IA | C7: 5500000 | D7: =C7*1.08 -> 5940000 | E7: =D7*1.08 -> 6415200 | F7: Aumento del 8% del SMMLV
B8: Desarrollador front-end | C8: 3135524 | D8: =C8*1.08 -> 3386365.9 | E8: =D8*1.08 -> 3657275.2 | F8: Aumento del 8% del SMMLV
B9: Gastos de administracion | C9: =1000000+C23+C24 -> 1114737.2 | D9: =C9*1.5 -> 1672105.8 | E9: =D9*1.5 -> 2508158.8 | F9: suscripciones, contabilidad,licencias
B10: CDN + Seguridad Web | C10: 91756.89 | D10: =C10 -> 91756.89 | E10: =D10 -> 91756.89
B11: Dominio web (.com) | C11: 3667 | D11: =C11 -> 3667 | E11: =D11 -> 3667
B12: Gastos de venta | C12: 2000000 | D12: =D13*5 -> 5250000 | E12: =E13*9 -> 9922500
B13: CAC | C13: =C12/2 -> 1000000 | D13: =C13*1.05 -> 1050000 | E13: =D13*1.05 -> 1102500 | F13: aumento 5% ipc
B15: Subtotal Costos Variables
B16: Base de datos Cloud SQL | C16: 184215.33
B17: Almacenamiento imágenes (GCS Standard) | C17: 2118.48
B18: Backups automáticos BD | C18: 331.59
B19: Inferencia GPU | C19: =500*36.84 -> 18420
B21: Gastos de administracion
I22: Almacenamiento imágenes (GCS Standard) | J22: 25 GB x institucion al mes:
B23: Monitoreo, logs y alertas (GCP Monitoring) | C23: 100000 | J23: 2118.48
B24: Herramientas (Github) | C24: 14737.23
I25: Backups automáticos BD | J25: 331.59
I27: Inferencia GPU | J27: x cada paciente se cobra $36,84
B28: Costo variable por institución (mes) | C28: =C19+C18+C17+C16 -> 205085.4 | D28: =C28*1.05 -> 215339.67 | E28: =D28*1.05 -> 226106.65 | J28: =500*36.84 -> 18420
B29: Subtotal Costos variables | C29: =C28*C36 -> 4922049.6 | D29: =D28*D36 -> 18088532 | E29: =E28*E36 -> 43412477 | F29: 84,42 x gb
B30: Subtotal Costos mensuales | C30: =SUM(C29,C5) -> 16767735 | D30: =SUM(D29,D5) -> 34432428 | E30: =SUM(E29,E5) -> 66011035 | F30: 13,21 x gb
B33: Estimación del precio de venta y utilidades
F34: se estima 500 pacientes por mes, cada uno consume 50gb aprox | G34: =500*50 -> 25000 | H34: 25GB al mes
C35: Año 1 | D35: Año 2 | E35: Año 3
B36: No. instituciones promedio mensual | C36: 24 | D36: 84 | E36: 192
B37: Costo promedio por institución/mes | C37: =C30/24 -> 698655.61 | D37: =D30/84 -> 409909.86 | E37: =E30/192 -> 343807.48
B38: Precio con margen de utilidad (30%) | C38: =C37*1.3 -> 908252.3 | D38: =C38*1.05 -> 953664.91 | E38: =D38*1.05 -> 1001348.2
B39: Por percepción | C39: 2500000 | D39: =C39*1.05 -> 2625000 | E39: =D39*1.05 -> 2756250
B40: Según competencia (referencia mercado) | C40: 1200000 | D40: =C40*1.05 -> 1260000 | E40: =D40*1.05 -> 1323000
F41: Observación
B42: Ingresos mensuales promedio | C42: =C38*C36 -> 21798055 | D42: =D38*D36 -> 80107853 | E42: =E38*E36 -> 1.9225885e+08
A43: Alternativas de precio: | B43: Utilidad operacional promedio mensual | C43: =C42-C30 -> 5030320.4 | D43: =D42-D30 -> 45675425 | E43: =E42-E30 -> 1.2624781e+08
F45: aumento 5% por ipc
B46: Valoración de la empresa
B48: Valoración pre-money | C48: 100000000 | E48: Gastos unicos
B49: Inversión inicial (op. inicial + creación empresa) | C49: =C50+C51+Proyecciones!H15 -> 1.4406885e+08 | E49: Asesor medico reumatologo
B50: Operación inicial | C50: =F55+F56+F57 -> 17500000 | E50: Registro INVIMA
...
